Workbook

Sheet Savings
A1: Savings Instrument | B1: ROI (%) | C1: Inception Date | D1: Maturtiy Date | E1: Maturity/Investment Amount | F1: Savings Amount | G1: NOTES
A2: Savings Bank MIN BAL A/C
A3: SBI | B3: 2.7 | C3: N/A | D3: N/A | E3: N/A | F3: 25000 | G3: HOLD
A4: PNB | B4: 2.7 | C4: N/A | D4: N/A | E4: N/A | F4: 10000 | G4: HOLD
A5: HDFC | B5: 3 | C5: N/A | D5: N/A | E5: N/A | F5: 5000 | G5: HOLD
A6: ICICI | B6: 3 | C6: N/A | D6: N/A | E6: N/A | F6: 25000 | G6: HOLD
A7: Fixed Deposits
A8: SBI (Emergency Fund - Part 1) | B8: 7 | C8: - | D8: 47277 | E8: 400000 | F8: 370000 | G8: ALWAYS HOLD
A9: SBI (Emergency Fund - Part 1) | B9: 7.6 | C9: - | D9: 47277 | E9: 400000 | F9: 371000 | G9: ALWAYS HOLD
A10: HDFC (Cushion Fund - Part 1) | B10: 7.25 | C10: 45088 | D10: 24/07/2029 | E10: 169500 | F10: 162000 | G10: HOLD
A11: HDFC (Cushion Fund - Part 2) | B11: 7.4 | C11: 24/12/2024 | D11: 24/07/2029 | E11: 50000 | F11: 42000 | G11: HOLD
A12: HDFC (Investment Fund - Part 1) | B12: 6.5 | C12: 46114 | D12: 47211 | E12: 80000 | F12: 74000 | G12: HOLD
A13: HDFC (Investment Fund - Part 2) | B13: 6.5 | C13: 46057 | D13: 47181 | E13: 80000 | F13: 74000 | G13: HOLD
A14: PNB (Investment Fund - Part 3) | B14: 6.6 | C14: 27/07/2026 | D14: 14/10/2027 | E14: 300000 | F14: 275000 | G14: HOLD
A15: PNB (Investment Fund - Part 4) | B15: 6.6 | C15: 27/07/2026 | D15: 14/10/2027 | E15: 300000 | F15: 275000 | G15: HOLD
A16: ICICI - MOD Balance | B16: 6.5 | C16: N/A | D16: N/A | E16: N/A | F16: 5000000 | G16: HOLD
A17: Pension Funds
A18: Employee Provident Fund | B18: 8.25 | C18: 29/12/2016 | D18: N/A | E18: N/A | F18: 628524 | G18: ALWAYS HOLD
A19: National Pension Fund | B19: 7.99 | C19: 23/11/2020 | D19: N/A | E19: N/A | F19: 154358.69 | G19: ALWAYS HOLD
A20: Debt Funds
A21: Public Provident Fund | B21: 7.1 | C21: 30/11/2020 | D21: N/A | E21: N/A | F21: 1941574 | G21: HOLD
A22: Equity - MF/ELSS
A23: ICICI Nifty50 Index Fund (DG) | B23: Manual | C23: N/A | D23: N/A | E23: 800000 | F23: 800000 | G23: HOLD
A24: Parag Parekh Flexi Cap Fund (DG) | B24: Manual | C24: N/A | D24: N/A | E24: 250000 | F24: 250000 | G24: HOLD
A25: Quant Multi Asset Allocation Fund (DG) | B25: Manual | C25: N/A | D25: N/A | E25: 80000 | F25: 80000 | G25: HOLD
A26: Quant Multi Cap Fund (DG) | B26: Manual | C26: N/A | D26: N/A | E26: 65000 | F26: 65000 | G26: HOLD
A27: Equity - Indian Stokcs & US ETFs
A28: Indian Equity/ETF | B28: Manual | C28: N/A | D28: N/A | E28: 1300000 | F28: 1300000 | G28: N/A
A29: NASDAQ: MSFT | B29: Live | C29: N/A | D29: N/A | E29: 25 | F29: =B64*E29*B90 -> 1171847.8 | G29: N/A
A30: NASDAQ: ETF: QQQ | B30: Live | C30: 45692 | D30: N/A | E30: 25 | F30: =E30*B67*B90 -> 1707324.9 | G30: N/A
A31: NASDAQ: ETF: QQQM | B31: Live | C31: 45692 | D31: N/A | E31: 12 | F31: =E31*B68*B90 -> 337469.28 | G31: N/A
A32: NASDAQ: META | B32: Live | C32: 21/7/2025 | D32: N/A | E32: 15 | F32: =E32*B77*B90 -> 934842.07 | G32: N/A
A33: NASDAQ: DUOL | B33: Live | C33: 21/7/2025 | D33: N/A | E33: 12 | F33: =E33*B74*B90 -> 159301.7 | G33: N/A
A34: NASDAQ: TMDX | B34: Live | C34: 21/7/2025 | D34: N/A | E34: 0 | F34: =E34*B79*B90 -> 0 | G34: N/A
A35: NASDAQ: SOUN | B35: Live | C35: 46266 | D35: N/A | E35: 0 | F35: =E35*B85*B90 -> 0 | G35: N/A
A36: NASDAQ: AMD | B36: Live | C36: 46237 | D36: N/A | E36: 5 | F36: =E36*B90*B86 -> 248405.99 | G36: N/A
A37: NASDAQ: PLTR | B37: Live | C37: 46055 | D37: N/A | E37: 0 | F37: =E37*B84*B90 -> 0 | G37: N/A
A38: NASDAQ: ETF: S&P500: VOO | B38: Live | C38: N/A | D38: N/A | E38: 12 | F38: =E38*B66*B90 -> 801851.35 | G38: N/A
A39: NASDAQ: NFLX | B39: Live | C39: 21/7/2025 | D39: N/A | E39: 5 | F39: =E39*B78*B90 -> 36243.501 | G39: N/A
A40: NASDAQ: ETF: SOXX | B40: Live | C40: 21/7/2025 | D40: N/A | E40: 15 | F40: =E40*B70*B90 -> 760813.2 | G40: N/A
...

Sheet Wealth Projection
A1: HUSBAND | B1: Savings Instruments | C1: Amount | E1: Total saved till today | F1: Projected Total by May'26 | G1: Projected Total by May'27 | H1: Projected Total by May'28 | I1: Projected Total by May'29 | J1: Projected Total by May'30 | K1: Projected Total by May'31 | L1: Projected Total by May'32 | M1: Projected Total by May'33 | N1: Projected Total by May'34 | O1: Projected Total by May'35
B2: Indian Mutual Fund | C2: 50000 | E2: =Savings!F59 -> 19497947 | F2: =E2+(C9*2) -> 20012947 | G2: =F2+(C9*12) -> 23102947 | H2: =G2+(C9*12) -> 26192947 | I2: =H2+(C9*12) -> 29282947 | J2: =I2+(C9*12) -> 32372947 | K2: =J2+(C9*12) -> 35462947 | L2: =K2+(C9*12) -> 38552947 | M2: =L2+(C9*12) -> 41642947 | N2: =M2+(C9*12) -> 44732947 | O2: =N2+(C9*12) -> 47822947
B3: PPF | C3: 12500
B4: Crypto | C4: 10000
B5: US Equity Investment | C5: 100000
B6: Recurring Deposit (Flat) | C6: 35000
B7: Gold | C7: 30000
B8: NPS | C8: 20000
B9: Monthly Total Savings | C9: =SUM(C2:C8) -> 257500
A11: WIFE | B11: Savings Instruments | C11: Amount | E11: Total saved till today | F11: Projected Total by May'26 | G11: Projected Total by May'27 | H11: Projected Total by May'28 | I11: Projected Total by May'29 | J11: Projected Total by May'30 | K11: Projected Total by May'31 | L11: Projected Total by May'32 | M11: Projected Total by May'33 | N11: Projected Total by May'34 | O11: Projected Total by May'35
B12: Indian Mutual Fund | C12: 30000 | E12: 2094570.9 | F12: 2183570.9 | G12: 2717570.9 | H12: 3251570.9 | I12: 3785570.9 | J12: 4319570.9 | K12: 4853570.9 | L12: 5387570.9 | M12: 5921570.9 | N12: 6455570.9 | O12: 6989570.9
B13: PPF | C13: 12500
B14: Crypto | C14: 0
B15: US Equity Investment | C15: 75000
B16: NPS | C16: 10000
B17: Monthly Total Savings | C17: 44500
A19: Flat | B19: Husband's Contribution | C19: Wife's Contribution
B20: =E2*0.6 -> 11698768 | C20: 1256742.5
B21: Total Downpayment | C21: =SUM(B20:C20) -> 12955511

Sheet Fixed Expenses
A1: Expense Name | B1: Amount | C1: Location | D1: RD Amount Deducted per month | E1: Need/Due By Date | F1: Deduction Date | G1: Maturity Date | H1: Duration in months | I1: Total Deductions per month
A2: Rent Difference (Yearly) | B2: =2900*12 -> 34800 | C2: Kotak Main Balance | D2: N/A | E2: N/A | F2: Security deposit paid already. | G2: N/A | H2: N/A | I2: =SUM(D4,D6:D8) -> 9143
A3: Rent Security Difference | B3: 9800 | C3: Kotak Main Balance | D3: N/A | E3: N/A
A4: Car Insurance and | B4: 15000 | C4: ICICI iWish | D4: 2234 | E4: 46433 | F4: 1st of every month | G4: 46425 | H4: 11
A5: Car Annual Maintainance | B5: 12500 | C5: RD 1 | D5: per month | E5: 46447
A6: Term Insurance | B6: 21000 | C6: ICICI iWish RD 2 | D6: 1566 | E6: 46126 | F6: 1st of every month | G6: 46479 | H6: 12
A7: Annual Health Check-up | B7: 15000 | C7: ICICI iWish RD 3 | D7: 901 | E7: 46569 | F7: 1st of every month | G7: 46570 | H7: 15
A8: Annual ITR Tax Fees | B8: 50000 | C8: ICICI iWish RD 4 | D8: 4442 | E8: 46569 | F8: 1st of every month | G8: 46570 | H8: 11

Sheet Husband_Expenses
A1: Expense Name | B1: Expense Type | C1: Expense Amount | D1: Actual Amount (per month) | E1: % Saving of salary
A2: Necessary Expenses - Part 1
A3: Rent | B3: Monthly | C3: 31900 | D3: =C3 -> 31900 | E3: =SUM(D3:D5)/B29 -> 0.11306667
A4: Grocery | B4: Monthly | C4: 6500 | D4: =C4 -> 6500
A5: Vehicle: Fuel & Washing | B5: Monthly | C5: 4000 | D5: =C5 -> 4000
A6: Necessary Expenses - Part 2
A7: Restaurant/Pub/Food Orders | B7: Monthly | C7: 6500 | D7: 6000 | E7: =SUM(D7:D8)/B29 -> 0.021333333
A8: Clothes/Home Decor | B8: Monthly | C8: 2000 | D8: =C8 -> 2000
A9: Fixed Expenses
A10: Term Life Insurance | B10: Yearly | C10: 21000 | D10: ='Fixed Expenses'!I2 -> 9143 | E10: =D10/B29 -> 0.024381333
A11: Master Health Check-up | B11: Yearly | C11: 15000
A12: Car Maintenance | B12: Yearly | C12: 12500
A13: Car & Bike Insurance | B13: Yearly | C13: =15000+1500 -> 16500
A14: Savings
A15: Savings per month (Coming from Wealth Projection Sheet) | B15: Monthly | C15: ='Wealth Projection'!C9 -> 257500 | D15: =C15 -> 257500 | E15: =D15/B29 -> 0.68666667
A19: Travel Expenses
A20: Flight - Home | B20: Quarterly | C20: 25500 | D20: =C20/3 -> 8500 | E20: =D20/B29 -> 0.022666667
A21: Miscellaneous Expenses
A22: Personal Expenses | B22: Monthly | C22: 2500 | D22: =C22 -> 2500 | E22: =SUM(D22:D24)/Husband_Expenses!B29 -> 0.026666667
A23: Unexpected Expenses | B23: Monthly | C23: 2500 | D23: =C23 -> 2500
A24: Family Expenses (Fixed) | B24: Monthly | C24: 5000 | D24: =C24 -> 5000
A25: Total Utilization | D25: =SUM(D3:D24) -> 335543 | E25: =SUM(E3:E24) -> 0.89478133
A28: Type of Action | B28: Amount | C28: Notes | D28: % of salary / Bank
A29: Net Average Salary | B29: 375000 | C29: - | D29: 1
A30: Leftover Salary | B30: =B29-Husband_Expenses!D25 -> 39457 | C30: - | D30: =Table3[[#This Row],[Amount]]/B29 -> 0.10521867

Sheet Wife_Expenses
A1: Expense Name | B1: Expense Type | C1: Expense Amount | D1: Actual Amount (per month) | E1: % Saving of salary
A2: Necessary Expenses - Part 1
A3: Maintenance | B3: Monthly | C3: 2000 | D3: 2000 | E3: =SUM(D3:D8)/B30 -> 0.099371721
A4: Electricity | B4: Monthly | C4: 1000 | D4: 1000
A5: Internet | B5: Monthly | C5: 842 | D5: 842
A6: Maid | B6: Monthly | C6: 3000 | D6: 3000
A7: Cook | B7: Monthly | C7: 5500 | D7: 5500
A8: Grocery | B8: Monthly | C8: 5000 | D8: 3000
A9: Necessary Expenses - Part 2
A10: Restaurant/Pub/Club | B10: Monthly | C10: 4000 | D10: 4000 | E10: =SUM(D10:D11)/B30 -> 0.045339724
A11: Clothes/Home Decor | B11: Monthly | C11: 3000 | D11: 3000
A12: Savings
A13: Savings per month (Coming from Wealth Projection Sheet) | B13: Monthly | C13: ='Wealth Projection'!C17 -> 44500 | D13: =C13 -> 44500 | E13: =D13/B30 -> 0.2882311
A16: Travel Expenses
A17: Cab - Home | B17: Quarterly | C17: 2500 | D17: =C17 -> 2500 | E17: =SUM(D17:D20)/B30 -> 0.29146965
A18: Cab - Office | B18: Monthly | C18: 5000 | D18: =C18 -> 5000
A19: Flight - Home | B19: Quarterly | C19: 25000 | D19: =C19 -> 25000
A20: Annual Trip Savings | B20: Yearly | C20: 150000 | D20: 12500
A21: Miscellaneous Expenses
A22: Personal Expenses | B22: Monthly | C22: 5000 | D22: =C22 -> 5000 | E22: =SUM(D22:D24)/B30 -> 0.097156552
A23: Unexpected Expenses | B23: Monthly | C23: 5000 | D23: =C23 -> 5000
A24: Family Expenses | B24: Monthly | C24: 5000 | D24: 5000
A25: Total Utilization | D25: =SUM(D3:D24) -> 126842 | E25: =SUM(E3:E24) -> 0.82156875
A29: Expense Name | B29: Amount | C29: % of salary
A30: Net Average Salary | B30: 154390 | C30: 1
A31: Leftover Salary | B31: =B30-D25 -> 27548 | C31: =B31/B30 -> 0.17843125
